<mujoco model="ball2d_tracking">
    <compiler angle="radian" meshdir="assets" autolimits="true" />

    <visual>
        <headlight diffuse="0.6 0.6 0.6" ambient="0.3 0.3 0.3" specular="0 0 0" />
        <rgba haze="0.15 0.25 0.35 1" />
        <global azimuth="120" elevation="-20" />
        <scale framelength="10.0" />
    </visual>

    <default>
        <default class="ball2d_tracking">
            <material specular="0.5" shininess="0.25" />
            <general dyntype="none" biastype="affine" ctrlrange="-2.8973 2.8973" forcerange="-87 87" />
            <default class="visual">
                <geom contype="0" conaffinity="0" group="2" />
            </default>
            <default class="collision">
                <geom condim="4" />
            </default>
        </default>
    </default>

    <asset>
        <material class="ball2d_tracking" name="white" rgba="1 1 1 1" />
        <material class="ball2d_tracking" name="off_white" rgba="0.75 0.75 0.75 1" />
        <material class="ball2d_tracking" name="dark" specular="0" shininess="0.25"
            rgba="0.2 0.2 0.2 1" />

        <texture type="skybox" builtin="gradient" rgb1="0.3 0.5 0.7" rgb2="0 0 0" width="512"
            height="3072" />
        <texture type="2d" name="groundplane" builtin="checker" mark="edge" rgb1="0.2 0.3 0.4"
            rgb2="0.1 0.2 0.3"
            markrgb="0.8 0.8 0.8" width="300" height="300" />
        <material name="groundplane" texture="groundplane" texuniform="true" texrepeat="5 5"
            reflectance="0.2" />
    </asset>


    <worldbody>
        <light pos="0 0 1.5" dir="0 0 -1" directional="true" />
        <geom name="floor" size="0 0 0.05" type="plane" material="groundplane" />

        <body name="ball_link1" pos="0.0 0.0 0.5">
            <joint name="ball_joint1" axis="1 0 0" type="slide" />
            <joint name="ball_joint2" axis="0 1 0" type="slide" />
            <joint name="ball_joint3" axis="0 0 1" />
            <geom name="actor_visual_geom1" type="sphere" size="0.01 0.01 0.01"
                material="off_white" class="visual" />
            <geom name="actor_collision_geom1" type="sphere" size="0.005 0.005 0.005"
                class="collision"
                material="white" />
            <body name="ball_link2" pos="0.01 0.0 0.0">
                <geom name="actor_visual_geom2" type="sphere" size="0.005 0.005 0.005"
                    material="dark" class="visual" />
                <geom name="actor_collision_geom2" type="sphere" size="0.002 0.002 0.002"
                    class="collision" material="white" />
            </body>
        </body>

        <body name="landmark1_link" pos="0.5 0.5 0.5">
            <geom name="landmark1_geom" size="0.01 0.01 0.01" rgba="0.75 0.0 0.0 1" />
        </body>

        <body name="landmark2_link" pos="0.6 -0.5 0.5">
            <geom name="landmark2_geom" size="0.01 0.01 0.01" rgba="0.0 0.75 0.0 1" />
        </body>

        <body name="landmark3_link" pos="-0.5 -0.75 0.5">
            <geom name="landmark3_geom" size="0.01 0.01 0.01" rgba="0.0 0.0 0.75 1" />
        </body>

    </worldbody>

</mujoco>